2022-12-20 20:04:55,946:WARNING:
'cuml' is a soft dependency and not included in the pycaret installation. Please run: `pip install cuml` to install.
2022-12-20 20:04:55,947:WARNING:
'cuml' is a soft dependency and not included in the pycaret installation. Please run: `pip install cuml` to install.
2022-12-20 20:04:55,947:WARNING:
'cuml' is a soft dependency and not included in the pycaret installation. Please run: `pip install cuml` to install.
2022-12-20 20:04:55,947:WARNING:
'cuml' is a soft dependency and not included in the pycaret installation. Please run: `pip install cuml` to install.
2022-12-20 20:04:56,697:WARNING:
'prophet' is a soft dependency and not included in the pycaret installation. Please run: `pip install prophet` to install.
2022-12-20 20:04:59,879:INFO:PyCaret ClassificationExperiment
2022-12-20 20:04:59,879:INFO:Logging name: clf-default-name
2022-12-20 20:04:59,880:INFO:ML Usecase: MLUsecase.CLASSIFICATION
2022-12-20 20:04:59,880:INFO:version 3.0.0.rc5
2022-12-20 20:04:59,880:INFO:Initializing setup()
2022-12-20 20:04:59,880:INFO:self.USI: 2319
2022-12-20 20:04:59,880:INFO:self._variable_keys: {'log_plots_param', 'y_test', 'fix_imbalance', 'gpu_n_jobs_param', 'idx', 'y_train', 'X_test', 'exp_id', 'X_train', 'X', 'memory', 'fold_groups_param', 'gpu_param', 'exp_name_log', 'fold_generator', 'fold_shuffle_param', '_available_plots', 'target_param', 'is_multiclass', 'pipeline', 'USI', 'html_param', 'data', 'logging_param', 'seed', '_ml_usecase', 'n_jobs_param', 'y'}
2022-12-20 20:04:59,880:INFO:Checking environment
2022-12-20 20:04:59,880:INFO:python_version: 3.9.13
2022-12-20 20:04:59,880:INFO:python_build: ('main', 'Aug 25 2022 23:51:50')
2022-12-20 20:04:59,880:INFO:machine: AMD64
2022-12-20 20:04:59,880:INFO:platform: Windows-10-10.0.22621-SP0
2022-12-20 20:04:59,880:INFO:Memory: svmem(total=16983089152, available=7427284992, percent=56.3, used=9555804160, free=7427284992)
2022-12-20 20:04:59,880:INFO:Physical Core: 6
2022-12-20 20:04:59,880:INFO:Logical Core: 12
2022-12-20 20:04:59,880:INFO:Checking libraries
2022-12-20 20:04:59,880:INFO:System:
2022-12-20 20:04:59,880:INFO:    python: 3.9.13 (main, Aug 25 2022, 23:51:50) [MSC v.1916 64 bit (AMD64)]
2022-12-20 20:04:59,880:INFO:executable: C:\Users\ajink\anaconda3\python.exe
2022-12-20 20:04:59,880:INFO:   machine: Windows-10-10.0.22621-SP0
2022-12-20 20:04:59,880:INFO:PyCaret required dependencies:
2022-12-20 20:04:59,880:INFO:                 pip: 22.2.2
2022-12-20 20:04:59,881:INFO:          setuptools: 63.4.1
2022-12-20 20:04:59,881:INFO:             pycaret: 3.0.0rc5
2022-12-20 20:04:59,881:INFO:             IPython: 7.31.1
2022-12-20 20:04:59,881:INFO:          ipywidgets: 7.6.5
2022-12-20 20:04:59,881:INFO:                tqdm: 4.64.1
2022-12-20 20:04:59,881:INFO:               numpy: 1.21.5
2022-12-20 20:04:59,881:INFO:              pandas: 1.4.4
2022-12-20 20:04:59,881:INFO:              jinja2: 2.11.3
2022-12-20 20:04:59,881:INFO:               scipy: 1.9.1
2022-12-20 20:04:59,881:INFO:              joblib: 1.2.0
2022-12-20 20:04:59,881:INFO:             sklearn: 1.0.2
2022-12-20 20:04:59,881:INFO:                pyod: 1.0.7
2022-12-20 20:04:59,881:INFO:            imblearn: 0.10.0
2022-12-20 20:04:59,881:INFO:   category_encoders: 2.5.1.post0
2022-12-20 20:04:59,881:INFO:            lightgbm: 3.3.3
2022-12-20 20:04:59,881:INFO:               numba: 0.55.1
2022-12-20 20:04:59,881:INFO:            requests: 2.28.1
2022-12-20 20:04:59,881:INFO:          matplotlib: 3.5.2
2022-12-20 20:04:59,881:INFO:          scikitplot: 0.3.7
2022-12-20 20:04:59,882:INFO:         yellowbrick: 1.5
2022-12-20 20:04:59,882:INFO:              plotly: 5.9.0
2022-12-20 20:04:59,882:INFO:             kaleido: 0.2.1
2022-12-20 20:04:59,882:INFO:         statsmodels: 0.13.2
2022-12-20 20:04:59,882:INFO:              sktime: 0.14.1
2022-12-20 20:04:59,882:INFO:               tbats: 1.1.2
2022-12-20 20:04:59,882:INFO:            pmdarima: 2.0.2
2022-12-20 20:04:59,882:INFO:              psutil: 5.9.0
2022-12-20 20:04:59,882:INFO:PyCaret optional dependencies:
2022-12-20 20:04:59,898:INFO:                shap: Not installed
2022-12-20 20:04:59,898:INFO:           interpret: Not installed
2022-12-20 20:04:59,899:INFO:                umap: Not installed
2022-12-20 20:04:59,899:INFO:    pandas_profiling: Not installed
2022-12-20 20:04:59,899:INFO:  explainerdashboard: Not installed
2022-12-20 20:04:59,899:INFO:             autoviz: Not installed
2022-12-20 20:04:59,899:INFO:           fairlearn: Not installed
2022-12-20 20:04:59,899:INFO:             xgboost: Not installed
2022-12-20 20:04:59,899:INFO:            catboost: Not installed
2022-12-20 20:04:59,899:INFO:              kmodes: Not installed
2022-12-20 20:04:59,899:INFO:             mlxtend: Not installed
2022-12-20 20:04:59,899:INFO:       statsforecast: Not installed
2022-12-20 20:04:59,899:INFO:        tune_sklearn: Not installed
2022-12-20 20:04:59,899:INFO:                 ray: Not installed
2022-12-20 20:04:59,899:INFO:            hyperopt: Not installed
2022-12-20 20:04:59,899:INFO:              optuna: Not installed
2022-12-20 20:04:59,899:INFO:               skopt: Not installed
2022-12-20 20:04:59,899:INFO:              mlflow: Not installed
2022-12-20 20:04:59,899:INFO:              gradio: Not installed
2022-12-20 20:04:59,899:INFO:             fastapi: Not installed
2022-12-20 20:04:59,899:INFO:             uvicorn: Not installed
2022-12-20 20:04:59,899:INFO:              m2cgen: Not installed
2022-12-20 20:04:59,899:INFO:           evidently: Not installed
2022-12-20 20:04:59,899:INFO:                nltk: 3.7
2022-12-20 20:04:59,899:INFO:            pyLDAvis: Not installed
2022-12-20 20:04:59,899:INFO:              gensim: 4.1.2
2022-12-20 20:04:59,900:INFO:               spacy: Not installed
2022-12-20 20:04:59,900:INFO:           wordcloud: Not installed
2022-12-20 20:04:59,900:INFO:            textblob: Not installed
2022-12-20 20:04:59,900:INFO:               fugue: Not installed
2022-12-20 20:04:59,900:INFO:           streamlit: Not installed
2022-12-20 20:04:59,900:INFO:             prophet: Not installed
2022-12-20 20:04:59,900:INFO:None
2022-12-20 20:04:59,900:INFO:Set up data.
2022-12-20 20:05:00,064:INFO:Set up train/test split.
2022-12-20 20:05:00,603:INFO:Set up index.
2022-12-20 20:05:00,618:INFO:Set up folding strategy.
2022-12-20 20:05:00,618:INFO:Assigning column types.
2022-12-20 20:05:00,773:INFO:Engine successfully changes for model 'lr' to 'sklearn'.
2022-12-20 20:05:00,813:INFO:Engine for model 'knn' has not been set explicitly, hence returning None.
2022-12-20 20:05:00,815:INFO:Engine for model 'rbfsvm' has not been set explicitly, hence returning None.
2022-12-20 20:05:00,845:WARNING:
'xgboost' is a soft dependency and not included in the pycaret installation. Please run: `pip install xgboost` to install.
Alternately, you can install this by running `pip install pycaret[models]`
2022-12-20 20:05:00,976:WARNING:
'catboost' is a soft dependency and not included in the pycaret installation. Please run: `pip install catboost` to install.
Alternately, you can install this by running `pip install pycaret[models]`
2022-12-20 20:05:01,016:INFO:Engine for model 'knn' has not been set explicitly, hence returning None.
2022-12-20 20:05:01,016:INFO:Engine for model 'rbfsvm' has not been set explicitly, hence returning None.
2022-12-20 20:05:01,041:WARNING:
'xgboost' is a soft dependency and not included in the pycaret installation. Please run: `pip install xgboost` to install.
Alternately, you can install this by running `pip install pycaret[models]`
2022-12-20 20:05:01,041:WARNING:
'catboost' is a soft dependency and not included in the pycaret installation. Please run: `pip install catboost` to install.
Alternately, you can install this by running `pip install pycaret[models]`
2022-12-20 20:05:01,041:INFO:Engine successfully changes for model 'knn' to 'sklearn'.
2022-12-20 20:05:01,081:INFO:Engine for model 'rbfsvm' has not been set explicitly, hence returning None.
2022-12-20 20:05:01,105:WARNING:
'xgboost' is a soft dependency and not included in the pycaret installation. Please run: `pip install xgboost` to install.
Alternately, you can install this by running `pip install pycaret[models]`
2022-12-20 20:05:01,105:WARNING:
'catboost' is a soft dependency and not included in the pycaret installation. Please run: `pip install catboost` to install.
Alternately, you can install this by running `pip install pycaret[models]`
2022-12-20 20:05:01,145:INFO:Engine for model 'rbfsvm' has not been set explicitly, hence returning None.
2022-12-20 20:05:01,169:WARNING:
'xgboost' is a soft dependency and not included in the pycaret installation. Please run: `pip install xgboost` to install.
Alternately, you can install this by running `pip install pycaret[models]`
2022-12-20 20:05:01,169:WARNING:
'catboost' is a soft dependency and not included in the pycaret installation. Please run: `pip install catboost` to install.
Alternately, you can install this by running `pip install pycaret[models]`
2022-12-20 20:05:01,170:INFO:Engine successfully changes for model 'rbfsvm' to 'sklearn'.
2022-12-20 20:05:01,234:WARNING:
'xgboost' is a soft dependency and not included in the pycaret installation. Please run: `pip install xgboost` to install.
Alternately, you can install this by running `pip install pycaret[models]`
2022-12-20 20:05:01,234:WARNING:
'catboost' is a soft dependency and not included in the pycaret installation. Please run: `pip install catboost` to install.
Alternately, you can install this by running `pip install pycaret[models]`
2022-12-20 20:05:01,299:WARNING:
'xgboost' is a soft dependency and not included in the pycaret installation. Please run: `pip install xgboost` to install.
Alternately, you can install this by running `pip install pycaret[models]`
2022-12-20 20:05:01,299:WARNING:
'catboost' is a soft dependency and not included in the pycaret installation. Please run: `pip install catboost` to install.
Alternately, you can install this by running `pip install pycaret[models]`
2022-12-20 20:05:01,300:INFO:Preparing preprocessing pipeline...
2022-12-20 20:05:01,334:INFO:Set up label encoding.
2022-12-20 20:05:01,334:INFO:Set up simple imputation.
2022-12-20 20:05:02,631:INFO:Finished creating preprocessing pipeline.
2022-12-20 20:05:02,635:INFO:Pipeline: Pipeline(memory=Memory(location=C:\Users\ajink\AppData\Local\Temp\joblib),
         steps=[('label_encoding',
                 TransformerWrapperWithInverse(exclude=None, include=None,
                                               transformer=LabelEncoder())),
                ('numerical_imputer',
                 TransformerWrapper(exclude=None,
                                    include=['USMER_2', 'MEDICAL_UNIT_2',
                                             'MEDICAL_UNIT_3', 'MEDICAL_UNIT_4',
                                             'MEDICAL_UNIT_5', 'MEDICAL_UNIT_6',
                                             'MEDICAL_...
                                             'CLASIFFICATION_FINAL_3', ...],
                                    transformer=SimpleImputer(add_indicator=False,
                                                              copy=True,
                                                              fill_value=None,
                                                              missing_values=nan,
                                                              strategy='mean',
                                                              verbose=0))),
                ('categorical_imputer',
                 TransformerWrapper(exclude=None, include=[],
                                    transformer=SimpleImputer(add_indicator=False,
                                                              copy=True,
                                                              fill_value=None,
                                                              missing_values=nan,
                                                              strategy='most_frequent',
                                                              verbose=0)))],
         verbose=False)
2022-12-20 20:05:02,635:INFO:Creating final display dataframe.
2022-12-20 20:05:09,788:INFO:Setup _display_container:                     Description             Value
0                    Session id               538
1                        Target            Target
2                   Target type            Binary
3                Target mapping        1: 0, 2: 1
4           Original data shape     (1048575, 36)
5        Transformed data shape     (1048575, 36)
6   Transformed train set shape      (734002, 36)
7    Transformed test set shape      (314573, 36)
8              Numeric features                35
9                    Preprocess              True
10              Imputation type            simple
11           Numeric imputation              mean
12       Categorical imputation              mode
13               Fold Generator   StratifiedKFold
14                  Fold Number                10
15                     CPU Jobs                -1
16                      Use GPU             False
17               Log Experiment             False
18              Experiment Name  clf-default-name
19                          USI              2319
2022-12-20 20:05:09,859:WARNING:
'xgboost' is a soft dependency and not included in the pycaret installation. Please run: `pip install xgboost` to install.
Alternately, you can install this by running `pip install pycaret[models]`
2022-12-20 20:05:09,859:WARNING:
'catboost' is a soft dependency and not included in the pycaret installation. Please run: `pip install catboost` to install.
Alternately, you can install this by running `pip install pycaret[models]`
2022-12-20 20:05:09,923:WARNING:
'xgboost' is a soft dependency and not included in the pycaret installation. Please run: `pip install xgboost` to install.
Alternately, you can install this by running `pip install pycaret[models]`
2022-12-20 20:05:09,924:WARNING:
'catboost' is a soft dependency and not included in the pycaret installation. Please run: `pip install catboost` to install.
Alternately, you can install this by running `pip install pycaret[models]`
2022-12-20 20:05:09,924:INFO:setup() successfully completed in 10.05s...............
2022-12-20 20:05:35,179:INFO:Initializing compare_models()
2022-12-20 20:05:35,179:INFO:compare_models(self=<pycaret.classification.oop.ClassificationExperiment object at 0x0000019A10B46FD0>, include=None, fold=None, round=4, cross_validation=True, sort=Accuracy, n_select=1, budget_time=None, turbo=True, errors=ignore, fit_kwargs=None, groups=None, experiment_custom_tags=None, probability_threshold=None, verbose=True, parallel=None, caller_params={'self': <pycaret.classification.oop.ClassificationExperiment object at 0x0000019A10B46FD0>, 'include': None, 'exclude': None, 'fold': None, 'round': 4, 'cross_validation': True, 'sort': 'Accuracy', 'n_select': 1, 'budget_time': None, 'turbo': True, 'errors': 'ignore', 'fit_kwargs': None, 'groups': None, 'experiment_custom_tags': None, 'probability_threshold': None, 'engine': None, 'verbose': True, 'parallel': None, '__class__': <class 'pycaret.classification.oop.ClassificationExperiment'>}, exclude=None)
2022-12-20 20:05:35,179:INFO:Checking exceptions
2022-12-20 20:05:35,436:INFO:Preparing display monitor
2022-12-20 20:05:35,467:INFO:Initializing Logistic Regression
2022-12-20 20:05:35,467:INFO:Total runtime is 0.0 minutes
2022-12-20 20:05:35,467:INFO:SubProcess create_model() called ==================================
2022-12-20 20:05:35,467:INFO:Initializing create_model()
2022-12-20 20:05:35,467:INFO:create_model(self=<pycaret.classification.oop.ClassificationExperiment object at 0x0000019A10B46FD0>, estimator=lr, fold=StratifiedKFold(n_splits=10, random_state=None, shuffle=False), round=4, cross_validation=True, predict=True, fit_kwargs={}, groups=None, refit=False, probability_threshold=None, experiment_custom_tags=None, verbose=False, system=False, add_to_model_list=True, metrics=None, display=<pycaret.internal.display.display.CommonDisplay object at 0x0000019A0E1E3EB0>, model_only=True, return_train_score=False, kwargs={})
2022-12-20 20:05:35,467:INFO:Checking exceptions
2022-12-20 20:05:35,467:INFO:Importing libraries
2022-12-20 20:05:35,467:INFO:Copying training dataset
2022-12-20 20:05:35,809:INFO:Defining folds
2022-12-20 20:05:35,809:INFO:Declaring metric variables
2022-12-20 20:05:35,809:INFO:Importing untrained model
2022-12-20 20:05:35,809:INFO:Logistic Regression Imported successfully
2022-12-20 20:05:35,809:INFO:Starting cross validation
2022-12-20 20:05:35,824:INFO:Cross validating with StratifiedKFold(n_splits=10, random_state=None, shuffle=False), n_jobs=-1
2022-12-20 20:07:01,033:WARNING:create_model() for lr raised an exception or returned all 0.0, trying without fit_kwargs:
2022-12-20 20:07:01,044:WARNING:Traceback (most recent call last):
  File "C:\Users\ajink\anaconda3\lib\site-packages\joblib\parallel.py", line 975, in retrieve
    self._output.extend(job.get(timeout=self.timeout))
  File "C:\Users\ajink\anaconda3\lib\site-packages\joblib\_parallel_backends.py", line 567, in wrap_future_result
    return future.result(timeout=timeout)
  File "C:\Users\ajink\anaconda3\lib\concurrent\futures\_base.py", line 441, in result
    self._condition.wait(timeout)
  File "C:\Users\ajink\anaconda3\lib\threading.py", line 312, in wait
    waiter.acquire()
KeyboardInterrupt

During handling of the above exception, another exception occurred:

Traceback (most recent call last):
  File "C:\Users\ajink\anaconda3\lib\site-packages\joblib\parallel.py", line 1098, in __call__
    self.retrieve()
  File "C:\Users\ajink\anaconda3\lib\site-packages\joblib\parallel.py", line 997, in retrieve
    backend.abort_everything(ensure_ready=ensure_ready)
  File "C:\Users\ajink\anaconda3\lib\site-packages\joblib\_parallel_backends.py", line 586, in abort_everything
    self._workers.terminate(kill_workers=True)
  File "C:\Users\ajink\anaconda3\lib\site-packages\joblib\executor.py", line 86, in terminate
    self._temp_folder_manager._unregister_temporary_resources()
  File "C:\Users\ajink\anaconda3\lib\site-packages\joblib\_memmapping_reducer.py", line 639, in _unregister_temporary_resources
    self._unregister_temporary_resources(context_id)
  File "C:\Users\ajink\anaconda3\lib\site-packages\joblib\_memmapping_reducer.py", line 644, in _unregister_temporary_resources
    resource_tracker.unregister(
  File "C:\Users\ajink\anaconda3\lib\site-packages\joblib\externals\loky\backend\resource_tracker.py", line 183, in unregister
    self.ensure_running()
  File "C:\Users\ajink\anaconda3\lib\site-packages\joblib\externals\loky\backend\resource_tracker.py", line 99, in ensure_running
    if self._check_alive():
  File "C:\Users\ajink\anaconda3\lib\site-packages\joblib\externals\loky\backend\resource_tracker.py", line 170, in _check_alive
    self._send('PROBE', '', '')
  File "C:\Users\ajink\anaconda3\lib\site-packages\joblib\externals\loky\backend\resource_tracker.py", line 197, in _send
    nbytes = os.write(self._fd, msg)
OSError: [Errno 22] Invalid argument

During handling of the above exception, another exception occurred:

Traceback (most recent call last):
  File "C:\Users\ajink\anaconda3\lib\site-packages\pycaret\internal\pycaret_experiment\supervised_experiment.py", line 793, in compare_models
    model, model_fit_time = self._create_model(**create_model_args)
  File "C:\Users\ajink\anaconda3\lib\site-packages\pycaret\internal\pycaret_experiment\supervised_experiment.py", line 1524, in _create_model
    model, model_fit_time, model_results, _ = self._create_model_with_cv(
  File "C:\Users\ajink\anaconda3\lib\site-packages\pycaret\internal\pycaret_experiment\supervised_experiment.py", line 1116, in _create_model_with_cv
    scores = cross_validate(
  File "C:\Users\ajink\anaconda3\lib\site-packages\sklearn\model_selection\_validation.py", line 267, in cross_validate
    results = parallel(
  File "C:\Users\ajink\anaconda3\lib\site-packages\joblib\parallel.py", line 1108, in __call__
    self._terminate_backend()
  File "C:\Users\ajink\anaconda3\lib\site-packages\joblib\parallel.py", line 799, in _terminate_backend
    self._backend.terminate()
  File "C:\Users\ajink\anaconda3\lib\site-packages\joblib\_parallel_backends.py", line 576, in terminate
    self._workers._temp_folder_manager._unlink_temporary_resources(
  File "C:\Users\ajink\anaconda3\lib\site-packages\joblib\_memmapping_reducer.py", line 628, in _unlink_temporary_resources
    resource_tracker.maybe_unlink(
  File "C:\Users\ajink\anaconda3\lib\site-packages\joblib\externals\loky\backend\resource_tracker.py", line 188, in maybe_unlink
    self.ensure_running()
  File "C:\Users\ajink\anaconda3\lib\site-packages\joblib\externals\loky\backend\resource_tracker.py", line 99, in ensure_running
    if self._check_alive():
  File "C:\Users\ajink\anaconda3\lib\site-packages\joblib\externals\loky\backend\resource_tracker.py", line 170, in _check_alive
    self._send('PROBE', '', '')
  File "C:\Users\ajink\anaconda3\lib\site-packages\joblib\externals\loky\backend\resource_tracker.py", line 197, in _send
    nbytes = os.write(self._fd, msg)
OSError: [Errno 22] Invalid argument

2022-12-20 20:07:01,044:INFO:Initializing create_model()
2022-12-20 20:07:01,045:INFO:create_model(self=<pycaret.classification.oop.ClassificationExperiment object at 0x0000019A10B46FD0>, estimator=lr, fold=StratifiedKFold(n_splits=10, random_state=None, shuffle=False), round=4, cross_validation=True, predict=True, fit_kwargs={}, groups=None, refit=False, probability_threshold=None, experiment_custom_tags=None, verbose=False, system=False, add_to_model_list=True, metrics=None, display=<pycaret.internal.display.display.CommonDisplay object at 0x0000019A0E1E3EB0>, model_only=True, return_train_score=False, kwargs={})
2022-12-20 20:07:01,045:INFO:Checking exceptions
2022-12-20 20:07:01,045:INFO:Importing libraries
2022-12-20 20:07:01,045:INFO:Copying training dataset
2022-12-20 20:07:01,425:INFO:Defining folds
2022-12-20 20:07:01,425:INFO:Declaring metric variables
2022-12-20 20:07:01,429:INFO:Importing untrained model
2022-12-20 20:07:01,432:INFO:Logistic Regression Imported successfully
2022-12-20 20:07:01,438:INFO:Starting cross validation
2022-12-20 20:07:01,439:INFO:Cross validating with StratifiedKFold(n_splits=10, random_state=None, shuffle=False), n_jobs=-1
2022-12-20 20:07:01,440:ERROR:create_model() for lr raised an exception or returned all 0.0:
2022-12-20 20:07:01,441:ERROR:Traceback (most recent call last):
  File "C:\Users\ajink\anaconda3\lib\site-packages\joblib\parallel.py", line 975, in retrieve
    self._output.extend(job.get(timeout=self.timeout))
  File "C:\Users\ajink\anaconda3\lib\site-packages\joblib\_parallel_backends.py", line 567, in wrap_future_result
    return future.result(timeout=timeout)
  File "C:\Users\ajink\anaconda3\lib\concurrent\futures\_base.py", line 441, in result
    self._condition.wait(timeout)
  File "C:\Users\ajink\anaconda3\lib\threading.py", line 312, in wait
    waiter.acquire()
KeyboardInterrupt

During handling of the above exception, another exception occurred:

Traceback (most recent call last):
  File "C:\Users\ajink\anaconda3\lib\site-packages\joblib\parallel.py", line 1098, in __call__
    self.retrieve()
  File "C:\Users\ajink\anaconda3\lib\site-packages\joblib\parallel.py", line 997, in retrieve
    backend.abort_everything(ensure_ready=ensure_ready)
  File "C:\Users\ajink\anaconda3\lib\site-packages\joblib\_parallel_backends.py", line 586, in abort_everything
    self._workers.terminate(kill_workers=True)
  File "C:\Users\ajink\anaconda3\lib\site-packages\joblib\executor.py", line 86, in terminate
    self._temp_folder_manager._unregister_temporary_resources()
  File "C:\Users\ajink\anaconda3\lib\site-packages\joblib\_memmapping_reducer.py", line 639, in _unregister_temporary_resources
    self._unregister_temporary_resources(context_id)
  File "C:\Users\ajink\anaconda3\lib\site-packages\joblib\_memmapping_reducer.py", line 644, in _unregister_temporary_resources
    resource_tracker.unregister(
  File "C:\Users\ajink\anaconda3\lib\site-packages\joblib\externals\loky\backend\resource_tracker.py", line 183, in unregister
    self.ensure_running()
  File "C:\Users\ajink\anaconda3\lib\site-packages\joblib\externals\loky\backend\resource_tracker.py", line 99, in ensure_running
    if self._check_alive():
  File "C:\Users\ajink\anaconda3\lib\site-packages\joblib\externals\loky\backend\resource_tracker.py", line 170, in _check_alive
    self._send('PROBE', '', '')
  File "C:\Users\ajink\anaconda3\lib\site-packages\joblib\externals\loky\backend\resource_tracker.py", line 197, in _send
    nbytes = os.write(self._fd, msg)
OSError: [Errno 22] Invalid argument

During handling of the above exception, another exception occurred:

Traceback (most recent call last):
  File "C:\Users\ajink\anaconda3\lib\site-packages\pycaret\internal\pycaret_experiment\supervised_experiment.py", line 793, in compare_models
    model, model_fit_time = self._create_model(**create_model_args)
  File "C:\Users\ajink\anaconda3\lib\site-packages\pycaret\internal\pycaret_experiment\supervised_experiment.py", line 1524, in _create_model
    model, model_fit_time, model_results, _ = self._create_model_with_cv(
  File "C:\Users\ajink\anaconda3\lib\site-packages\pycaret\internal\pycaret_experiment\supervised_experiment.py", line 1116, in _create_model_with_cv
    scores = cross_validate(
  File "C:\Users\ajink\anaconda3\lib\site-packages\sklearn\model_selection\_validation.py", line 267, in cross_validate
    results = parallel(
  File "C:\Users\ajink\anaconda3\lib\site-packages\joblib\parallel.py", line 1108, in __call__
    self._terminate_backend()
  File "C:\Users\ajink\anaconda3\lib\site-packages\joblib\parallel.py", line 799, in _terminate_backend
    self._backend.terminate()
  File "C:\Users\ajink\anaconda3\lib\site-packages\joblib\_parallel_backends.py", line 576, in terminate
    self._workers._temp_folder_manager._unlink_temporary_resources(
  File "C:\Users\ajink\anaconda3\lib\site-packages\joblib\_memmapping_reducer.py", line 628, in _unlink_temporary_resources
    resource_tracker.maybe_unlink(
  File "C:\Users\ajink\anaconda3\lib\site-packages\joblib\externals\loky\backend\resource_tracker.py", line 188, in maybe_unlink
    self.ensure_running()
  File "C:\Users\ajink\anaconda3\lib\site-packages\joblib\externals\loky\backend\resource_tracker.py", line 99, in ensure_running
    if self._check_alive():
  File "C:\Users\ajink\anaconda3\lib\site-packages\joblib\externals\loky\backend\resource_tracker.py", line 170, in _check_alive
    self._send('PROBE', '', '')
  File "C:\Users\ajink\anaconda3\lib\site-packages\joblib\externals\loky\backend\resource_tracker.py", line 197, in _send
    nbytes = os.write(self._fd, msg)
OSError: [Errno 22] Invalid argument

During handling of the above exception, another exception occurred:

Traceback (most recent call last):
  File "C:\Users\ajink\anaconda3\lib\site-packages\pycaret\internal\pycaret_experiment\supervised_experiment.py", line 809, in compare_models
    model, model_fit_time = self._create_model(**create_model_args)
  File "C:\Users\ajink\anaconda3\lib\site-packages\pycaret\internal\pycaret_experiment\supervised_experiment.py", line 1524, in _create_model
    model, model_fit_time, model_results, _ = self._create_model_with_cv(
  File "C:\Users\ajink\anaconda3\lib\site-packages\pycaret\internal\pycaret_experiment\supervised_experiment.py", line 1116, in _create_model_with_cv
    scores = cross_validate(
  File "C:\Users\ajink\anaconda3\lib\site-packages\sklearn\model_selection\_validation.py", line 267, in cross_validate
    results = parallel(
  File "C:\Users\ajink\anaconda3\lib\site-packages\joblib\parallel.py", line 1008, in __call__
    n_jobs = self._initialize_backend()
  File "C:\Users\ajink\anaconda3\lib\site-packages\joblib\parallel.py", line 775, in _initialize_backend
    n_jobs = self._backend.configure(n_jobs=self.n_jobs, parallel=self,
  File "C:\Users\ajink\anaconda3\lib\site-packages\joblib\_parallel_backends.py", line 506, in configure
    self._workers = get_memmapping_executor(
  File "C:\Users\ajink\anaconda3\lib\site-packages\joblib\executor.py", line 20, in get_memmapping_executor
    return MemmappingExecutor.get_memmapping_executor(n_jobs, **kwargs)
  File "C:\Users\ajink\anaconda3\lib\site-packages\joblib\executor.py", line 42, in get_memmapping_executor
    manager = TemporaryResourcesManager(temp_folder)
  File "C:\Users\ajink\anaconda3\lib\site-packages\joblib\_memmapping_reducer.py", line 535, in __init__
    self.set_current_context(context_id)
  File "C:\Users\ajink\anaconda3\lib\site-packages\joblib\_memmapping_reducer.py", line 539, in set_current_context
    self.register_new_context(context_id)
  File "C:\Users\ajink\anaconda3\lib\site-packages\joblib\_memmapping_reducer.py", line 564, in register_new_context
    self.register_folder_finalizer(new_folder_path, context_id)
  File "C:\Users\ajink\anaconda3\lib\site-packages\joblib\_memmapping_reducer.py", line 594, in register_folder_finalizer
    resource_tracker.register(pool_subfolder, "folder")
  File "C:\Users\ajink\anaconda3\lib\site-packages\joblib\externals\loky\backend\resource_tracker.py", line 178, in register
    self.ensure_running()
  File "C:\Users\ajink\anaconda3\lib\site-packages\joblib\externals\loky\backend\resource_tracker.py", line 99, in ensure_running
    if self._check_alive():
  File "C:\Users\ajink\anaconda3\lib\site-packages\joblib\externals\loky\backend\resource_tracker.py", line 170, in _check_alive
    self._send('PROBE', '', '')
  File "C:\Users\ajink\anaconda3\lib\site-packages\joblib\externals\loky\backend\resource_tracker.py", line 197, in _send
    nbytes = os.write(self._fd, msg)
OSError: [Errno 22] Invalid argument

2022-12-20 20:07:01,445:INFO:Initializing K Neighbors Classifier
2022-12-20 20:07:01,445:INFO:Total runtime is 1.43295867840449 minutes
2022-12-20 20:07:01,448:INFO:SubProcess create_model() called ==================================
2022-12-20 20:07:01,448:INFO:Initializing create_model()
2022-12-20 20:07:01,448:INFO:create_model(self=<pycaret.classification.oop.ClassificationExperiment object at 0x0000019A10B46FD0>, estimator=knn, fold=StratifiedKFold(n_splits=10, random_state=None, shuffle=False), round=4, cross_validation=True, predict=True, fit_kwargs={}, groups=None, refit=False, probability_threshold=None, experiment_custom_tags=None, verbose=False, system=False, add_to_model_list=True, metrics=None, display=<pycaret.internal.display.display.CommonDisplay object at 0x0000019A0E1E3EB0>, model_only=True, return_train_score=False, kwargs={})
2022-12-20 20:07:01,448:INFO:Checking exceptions
2022-12-20 20:07:01,448:INFO:Importing libraries
2022-12-20 20:07:01,448:INFO:Copying training dataset
2022-12-20 20:07:01,835:INFO:Defining folds
2022-12-20 20:07:01,835:INFO:Declaring metric variables
2022-12-20 20:07:01,843:INFO:Importing untrained model
2022-12-20 20:07:01,849:INFO:K Neighbors Classifier Imported successfully
2022-12-20 20:07:01,860:INFO:Starting cross validation
2022-12-20 20:07:01,861:INFO:Cross validating with StratifiedKFold(n_splits=10, random_state=None, shuffle=False), n_jobs=-1
2022-12-20 20:07:01,862:WARNING:create_model() for knn raised an exception or returned all 0.0, trying without fit_kwargs:
2022-12-20 20:07:01,862:WARNING:Traceback (most recent call last):
  File "C:\Users\ajink\anaconda3\lib\site-packages\pycaret\internal\pycaret_experiment\supervised_experiment.py", line 793, in compare_models
    model, model_fit_time = self._create_model(**create_model_args)
  File "C:\Users\ajink\anaconda3\lib\site-packages\pycaret\internal\pycaret_experiment\supervised_experiment.py", line 1524, in _create_model
    model, model_fit_time, model_results, _ = self._create_model_with_cv(
  File "C:\Users\ajink\anaconda3\lib\site-packages\pycaret\internal\pycaret_experiment\supervised_experiment.py", line 1116, in _create_model_with_cv
    scores = cross_validate(
  File "C:\Users\ajink\anaconda3\lib\site-packages\sklearn\model_selection\_validation.py", line 267, in cross_validate
    results = parallel(
  File "C:\Users\ajink\anaconda3\lib\site-packages\joblib\parallel.py", line 1008, in __call__
    n_jobs = self._initialize_backend()
  File "C:\Users\ajink\anaconda3\lib\site-packages\joblib\parallel.py", line 775, in _initialize_backend
    n_jobs = self._backend.configure(n_jobs=self.n_jobs, parallel=self,
  File "C:\Users\ajink\anaconda3\lib\site-packages\joblib\_parallel_backends.py", line 506, in configure
    self._workers = get_memmapping_executor(
  File "C:\Users\ajink\anaconda3\lib\site-packages\joblib\executor.py", line 20, in get_memmapping_executor
    return MemmappingExecutor.get_memmapping_executor(n_jobs, **kwargs)
  File "C:\Users\ajink\anaconda3\lib\site-packages\joblib\executor.py", line 42, in get_memmapping_executor
    manager = TemporaryResourcesManager(temp_folder)
  File "C:\Users\ajink\anaconda3\lib\site-packages\joblib\_memmapping_reducer.py", line 535, in __init__
    self.set_current_context(context_id)
  File "C:\Users\ajink\anaconda3\lib\site-packages\joblib\_memmapping_reducer.py", line 539, in set_current_context
    self.register_new_context(context_id)
  File "C:\Users\ajink\anaconda3\lib\site-packages\joblib\_memmapping_reducer.py", line 564, in register_new_context
    self.register_folder_finalizer(new_folder_path, context_id)
  File "C:\Users\ajink\anaconda3\lib\site-packages\joblib\_memmapping_reducer.py", line 594, in register_folder_finalizer
    resource_tracker.register(pool_subfolder, "folder")
  File "C:\Users\ajink\anaconda3\lib\site-packages\joblib\externals\loky\backend\resource_tracker.py", line 178, in register
    self.ensure_running()
  File "C:\Users\ajink\anaconda3\lib\site-packages\joblib\externals\loky\backend\resource_tracker.py", line 99, in ensure_running
    if self._check_alive():
  File "C:\Users\ajink\anaconda3\lib\site-packages\joblib\externals\loky\backend\resource_tracker.py", line 170, in _check_alive
    self._send('PROBE', '', '')
  File "C:\Users\ajink\anaconda3\lib\site-packages\joblib\externals\loky\backend\resource_tracker.py", line 197, in _send
    nbytes = os.write(self._fd, msg)
OSError: [Errno 22] Invalid argument

2022-12-20 20:07:01,863:INFO:Initializing create_model()
2022-12-20 20:07:01,863:INFO:create_model(self=<pycaret.classification.oop.ClassificationExperiment object at 0x0000019A10B46FD0>, estimator=knn, fold=StratifiedKFold(n_splits=10, random_state=None, shuffle=False), round=4, cross_validation=True, predict=True, fit_kwargs={}, groups=None, refit=False, probability_threshold=None, experiment_custom_tags=None, verbose=False, system=False, add_to_model_list=True, metrics=None, display=<pycaret.internal.display.display.CommonDisplay object at 0x0000019A0E1E3EB0>, model_only=True, return_train_score=False, kwargs={})
2022-12-20 20:07:01,863:INFO:Checking exceptions
2022-12-20 20:07:01,863:INFO:Importing libraries
2022-12-20 20:07:01,863:INFO:Copying training dataset
2022-12-20 20:07:02,208:INFO:Defining folds
2022-12-20 20:07:02,208:INFO:Declaring metric variables
2022-12-20 20:07:02,211:INFO:Importing untrained model
2022-12-20 20:07:02,215:INFO:K Neighbors Classifier Imported successfully
2022-12-20 20:07:02,221:INFO:Starting cross validation
2022-12-20 20:07:02,222:INFO:Cross validating with StratifiedKFold(n_splits=10, random_state=None, shuffle=False), n_jobs=-1
2022-12-20 20:07:02,223:ERROR:create_model() for knn raised an exception or returned all 0.0:
2022-12-20 20:07:02,223:ERROR:Traceback (most recent call last):
  File "C:\Users\ajink\anaconda3\lib\site-packages\pycaret\internal\pycaret_experiment\supervised_experiment.py", line 793, in compare_models
    model, model_fit_time = self._create_model(**create_model_args)
  File "C:\Users\ajink\anaconda3\lib\site-packages\pycaret\internal\pycaret_experiment\supervised_experiment.py", line 1524, in _create_model
    model, model_fit_time, model_results, _ = self._create_model_with_cv(
  File "C:\Users\ajink\anaconda3\lib\site-packages\pycaret\internal\pycaret_experiment\supervised_experiment.py", line 1116, in _create_model_with_cv
    scores = cross_validate(
  File "C:\Users\ajink\anaconda3\lib\site-packages\sklearn\model_selection\_validation.py", line 267, in cross_validate
    results = parallel(
  File "C:\Users\ajink\anaconda3\lib\site-packages\joblib\parallel.py", line 1008, in __call__
    n_jobs = self._initialize_backend()
  File "C:\Users\ajink\anaconda3\lib\site-packages\joblib\parallel.py", line 775, in _initialize_backend
    n_jobs = self._backend.configure(n_jobs=self.n_jobs, parallel=self,
  File "C:\Users\ajink\anaconda3\lib\site-packages\joblib\_parallel_backends.py", line 506, in configure
    self._workers = get_memmapping_executor(
  File "C:\Users\ajink\anaconda3\lib\site-packages\joblib\executor.py", line 20, in get_memmapping_executor
    return MemmappingExecutor.get_memmapping_executor(n_jobs, **kwargs)
  File "C:\Users\ajink\anaconda3\lib\site-packages\joblib\executor.py", line 42, in get_memmapping_executor
    manager = TemporaryResourcesManager(temp_folder)
  File "C:\Users\ajink\anaconda3\lib\site-packages\joblib\_memmapping_reducer.py", line 535, in __init__
    self.set_current_context(context_id)
  File "C:\Users\ajink\anaconda3\lib\site-packages\joblib\_memmapping_reducer.py", line 539, in set_current_context
    self.register_new_context(context_id)
  File "C:\Users\ajink\anaconda3\lib\site-packages\joblib\_memmapping_reducer.py", line 564, in register_new_context
    self.register_folder_finalizer(new_folder_path, context_id)
  File "C:\Users\ajink\anaconda3\lib\site-packages\joblib\_memmapping_reducer.py", line 594, in register_folder_finalizer
    resource_tracker.register(pool_subfolder, "folder")
  File "C:\Users\ajink\anaconda3\lib\site-packages\joblib\externals\loky\backend\resource_tracker.py", line 178, in register
    self.ensure_running()
  File "C:\Users\ajink\anaconda3\lib\site-packages\joblib\externals\loky\backend\resource_tracker.py", line 99, in ensure_running
    if self._check_alive():
  File "C:\Users\ajink\anaconda3\lib\site-packages\joblib\externals\loky\backend\resource_tracker.py", line 170, in _check_alive
    self._send('PROBE', '', '')
  File "C:\Users\ajink\anaconda3\lib\site-packages\joblib\externals\loky\backend\resource_tracker.py", line 197, in _send
    nbytes = os.write(self._fd, msg)
OSError: [Errno 22] Invalid argument

During handling of the above exception, another exception occurred:

Traceback (most recent call last):
  File "C:\Users\ajink\anaconda3\lib\site-packages\pycaret\internal\pycaret_experiment\supervised_experiment.py", line 809, in compare_models
    model, model_fit_time = self._create_model(**create_model_args)
  File "C:\Users\ajink\anaconda3\lib\site-packages\pycaret\internal\pycaret_experiment\supervised_experiment.py", line 1524, in _create_model
    model, model_fit_time, model_results, _ = self._create_model_with_cv(
  File "C:\Users\ajink\anaconda3\lib\site-packages\pycaret\internal\pycaret_experiment\supervised_experiment.py", line 1116, in _create_model_with_cv
    scores = cross_validate(
  File "C:\Users\ajink\anaconda3\lib\site-packages\sklearn\model_selection\_validation.py", line 267, in cross_validate
    results = parallel(
  File "C:\Users\ajink\anaconda3\lib\site-packages\joblib\parallel.py", line 1008, in __call__
    n_jobs = self._initialize_backend()
  File "C:\Users\ajink\anaconda3\lib\site-packages\joblib\parallel.py", line 775, in _initialize_backend
    n_jobs = self._backend.configure(n_jobs=self.n_jobs, parallel=self,
  File "C:\Users\ajink\anaconda3\lib\site-packages\joblib\_parallel_backends.py", line 506, in configure
    self._workers = get_memmapping_executor(
  File "C:\Users\ajink\anaconda3\lib\site-packages\joblib\executor.py", line 20, in get_memmapping_executor
    return MemmappingExecutor.get_memmapping_executor(n_jobs, **kwargs)
  File "C:\Users\ajink\anaconda3\lib\site-packages\joblib\executor.py", line 42, in get_memmapping_executor
    manager = TemporaryResourcesManager(temp_folder)
  File "C:\Users\ajink\anaconda3\lib\site-packages\joblib\_memmapping_reducer.py", line 535, in __init__
    self.set_current_context(context_id)
  File "C:\Users\ajink\anaconda3\lib\site-packages\joblib\_memmapping_reducer.py", line 539, in set_current_context
    self.register_new_context(context_id)
  File "C:\Users\ajink\anaconda3\lib\site-packages\joblib\_memmapping_reducer.py", line 564, in register_new_context
    self.register_folder_finalizer(new_folder_path, context_id)
  File "C:\Users\ajink\anaconda3\lib\site-packages\joblib\_memmapping_reducer.py", line 594, in register_folder_finalizer
    resource_tracker.register(pool_subfolder, "folder")
  File "C:\Users\ajink\anaconda3\lib\site-packages\joblib\externals\loky\backend\resource_tracker.py", line 178, in register
    self.ensure_running()
  File "C:\Users\ajink\anaconda3\lib\site-packages\joblib\externals\loky\backend\resource_tracker.py", line 99, in ensure_running
    if self._check_alive():
  File "C:\Users\ajink\anaconda3\lib\site-packages\joblib\externals\loky\backend\resource_tracker.py", line 170, in _check_alive
    self._send('PROBE', '', '')
  File "C:\Users\ajink\anaconda3\lib\site-packages\joblib\externals\loky\backend\resource_tracker.py", line 197, in _send
    nbytes = os.write(self._fd, msg)
OSError: [Errno 22] Invalid argument

2022-12-20 20:07:02,228:INFO:Initializing Naive Bayes
2022-12-20 20:07:02,228:INFO:Total runtime is 1.4460113366444904 minutes
2022-12-20 20:07:02,231:INFO:SubProcess create_model() called ==================================
2022-12-20 20:07:02,231:INFO:Initializing create_model()
2022-12-20 20:07:02,231:INFO:create_model(self=<pycaret.classification.oop.ClassificationExperiment object at 0x0000019A10B46FD0>, estimator=nb, fold=StratifiedKFold(n_splits=10, random_state=None, shuffle=False), round=4, cross_validation=True, predict=True, fit_kwargs={}, groups=None, refit=False, probability_threshold=None, experiment_custom_tags=None, verbose=False, system=False, add_to_model_list=True, metrics=None, display=<pycaret.internal.display.display.CommonDisplay object at 0x0000019A0E1E3EB0>, model_only=True, return_train_score=False, kwargs={})
2022-12-20 20:07:02,231:INFO:Checking exceptions
2022-12-20 20:07:02,231:INFO:Importing libraries
2022-12-20 20:07:02,231:INFO:Copying training dataset
2022-12-20 20:07:02,565:INFO:Defining folds
2022-12-20 20:07:02,566:INFO:Declaring metric variables
2022-12-20 20:07:02,569:INFO:Importing untrained model
2022-12-20 20:07:02,572:INFO:Naive Bayes Imported successfully
2022-12-20 20:07:02,578:INFO:Starting cross validation
2022-12-20 20:07:02,579:INFO:Cross validating with StratifiedKFold(n_splits=10, random_state=None, shuffle=False), n_jobs=-1
2022-12-20 20:07:02,580:WARNING:create_model() for nb raised an exception or returned all 0.0, trying without fit_kwargs:
2022-12-20 20:07:02,580:WARNING:Traceback (most recent call last):
  File "C:\Users\ajink\anaconda3\lib\site-packages\pycaret\internal\pycaret_experiment\supervised_experiment.py", line 793, in compare_models
    model, model_fit_time = self._create_model(**create_model_args)
  File "C:\Users\ajink\anaconda3\lib\site-packages\pycaret\internal\pycaret_experiment\supervised_experiment.py", line 1524, in _create_model
    model, model_fit_time, model_results, _ = self._create_model_with_cv(
  File "C:\Users\ajink\anaconda3\lib\site-packages\pycaret\internal\pycaret_experiment\supervised_experiment.py", line 1116, in _create_model_with_cv
    scores = cross_validate(
  File "C:\Users\ajink\anaconda3\lib\site-packages\sklearn\model_selection\_validation.py", line 267, in cross_validate
    results = parallel(
  File "C:\Users\ajink\anaconda3\lib\site-packages\joblib\parallel.py", line 1008, in __call__
    n_jobs = self._initialize_backend()
  File "C:\Users\ajink\anaconda3\lib\site-packages\joblib\parallel.py", line 775, in _initialize_backend
    n_jobs = self._backend.configure(n_jobs=self.n_jobs, parallel=self,
  File "C:\Users\ajink\anaconda3\lib\site-packages\joblib\_parallel_backends.py", line 506, in configure
    self._workers = get_memmapping_executor(
  File "C:\Users\ajink\anaconda3\lib\site-packages\joblib\executor.py", line 20, in get_memmapping_executor
    return MemmappingExecutor.get_memmapping_executor(n_jobs, **kwargs)
  File "C:\Users\ajink\anaconda3\lib\site-packages\joblib\executor.py", line 42, in get_memmapping_executor
    manager = TemporaryResourcesManager(temp_folder)
  File "C:\Users\ajink\anaconda3\lib\site-packages\joblib\_memmapping_reducer.py", line 535, in __init__
    self.set_current_context(context_id)
  File "C:\Users\ajink\anaconda3\lib\site-packages\joblib\_memmapping_reducer.py", line 539, in set_current_context
    self.register_new_context(context_id)
  File "C:\Users\ajink\anaconda3\lib\site-packages\joblib\_memmapping_reducer.py", line 564, in register_new_context
    self.register_folder_finalizer(new_folder_path, context_id)
  File "C:\Users\ajink\anaconda3\lib\site-packages\joblib\_memmapping_reducer.py", line 594, in register_folder_finalizer
    resource_tracker.register(pool_subfolder, "folder")
  File "C:\Users\ajink\anaconda3\lib\site-packages\joblib\externals\loky\backend\resource_tracker.py", line 178, in register
    self.ensure_running()
  File "C:\Users\ajink\anaconda3\lib\site-packages\joblib\externals\loky\backend\resource_tracker.py", line 99, in ensure_running
    if self._check_alive():
  File "C:\Users\ajink\anaconda3\lib\site-packages\joblib\externals\loky\backend\resource_tracker.py", line 170, in _check_alive
    self._send('PROBE', '', '')
  File "C:\Users\ajink\anaconda3\lib\site-packages\joblib\externals\loky\backend\resource_tracker.py", line 197, in _send
    nbytes = os.write(self._fd, msg)
OSError: [Errno 22] Invalid argument

2022-12-20 20:07:02,580:INFO:Initializing create_model()
2022-12-20 20:07:02,581:INFO:create_model(self=<pycaret.classification.oop.ClassificationExperiment object at 0x0000019A10B46FD0>, estimator=nb, fold=StratifiedKFold(n_splits=10, random_state=None, shuffle=False), round=4, cross_validation=True, predict=True, fit_kwargs={}, groups=None, refit=False, probability_threshold=None, experiment_custom_tags=None, verbose=False, system=False, add_to_model_list=True, metrics=None, display=<pycaret.internal.display.display.CommonDisplay object at 0x0000019A0E1E3EB0>, model_only=True, return_train_score=False, kwargs={})
2022-12-20 20:07:02,581:INFO:Checking exceptions
2022-12-20 20:07:02,581:INFO:Importing libraries
2022-12-20 20:07:02,581:INFO:Copying training dataset
2022-12-20 20:07:02,921:INFO:Defining folds
2022-12-20 20:07:02,921:INFO:Declaring metric variables
2022-12-20 20:07:02,924:INFO:Importing untrained model
2022-12-20 20:07:02,928:INFO:Naive Bayes Imported successfully
2022-12-20 20:07:02,933:INFO:Starting cross validation
2022-12-20 20:07:02,934:INFO:Cross validating with StratifiedKFold(n_splits=10, random_state=None, shuffle=False), n_jobs=-1
2022-12-20 20:07:02,935:ERROR:create_model() for nb raised an exception or returned all 0.0:
2022-12-20 20:07:02,936:ERROR:Traceback (most recent call last):
  File "C:\Users\ajink\anaconda3\lib\site-packages\pycaret\internal\pycaret_experiment\supervised_experiment.py", line 793, in compare_models
    model, model_fit_time = self._create_model(**create_model_args)
  File "C:\Users\ajink\anaconda3\lib\site-packages\pycaret\internal\pycaret_experiment\supervised_experiment.py", line 1524, in _create_model
    model, model_fit_time, model_results, _ = self._create_model_with_cv(
  File "C:\Users\ajink\anaconda3\lib\site-packages\pycaret\internal\pycaret_experiment\supervised_experiment.py", line 1116, in _create_model_with_cv
    scores = cross_validate(
  File "C:\Users\ajink\anaconda3\lib\site-packages\sklearn\model_selection\_validation.py", line 267, in cross_validate
    results = parallel(
  File "C:\Users\ajink\anaconda3\lib\site-packages\joblib\parallel.py", line 1008, in __call__
    n_jobs = self._initialize_backend()
  File "C:\Users\ajink\anaconda3\lib\site-packages\joblib\parallel.py", line 775, in _initialize_backend
    n_jobs = self._backend.configure(n_jobs=self.n_jobs, parallel=self,
  File "C:\Users\ajink\anaconda3\lib\site-packages\joblib\_parallel_backends.py", line 506, in configure
    self._workers = get_memmapping_executor(
  File "C:\Users\ajink\anaconda3\lib\site-packages\joblib\executor.py", line 20, in get_memmapping_executor
    return MemmappingExecutor.get_memmapping_executor(n_jobs, **kwargs)
  File "C:\Users\ajink\anaconda3\lib\site-packages\joblib\executor.py", line 42, in get_memmapping_executor
    manager = TemporaryResourcesManager(temp_folder)
  File "C:\Users\ajink\anaconda3\lib\site-packages\joblib\_memmapping_reducer.py", line 535, in __init__
    self.set_current_context(context_id)
  File "C:\Users\ajink\anaconda3\lib\site-packages\joblib\_memmapping_reducer.py", line 539, in set_current_context
    self.register_new_context(context_id)
  File "C:\Users\ajink\anaconda3\lib\site-packages\joblib\_memmapping_reducer.py", line 564, in register_new_context
    self.register_folder_finalizer(new_folder_path, context_id)
  File "C:\Users\ajink\anaconda3\lib\site-packages\joblib\_memmapping_reducer.py", line 594, in register_folder_finalizer
    resource_tracker.register(pool_subfolder, "folder")
  File "C:\Users\ajink\anaconda3\lib\site-packages\joblib\externals\loky\backend\resource_tracker.py", line 178, in register
    self.ensure_running()
  File "C:\Users\ajink\anaconda3\lib\site-packages\joblib\externals\loky\backend\resource_tracker.py", line 99, in ensure_running
    if self._check_alive():
  File "C:\Users\ajink\anaconda3\lib\site-packages\joblib\externals\loky\backend\resource_tracker.py", line 170, in _check_alive
    self._send('PROBE', '', '')
  File "C:\Users\ajink\anaconda3\lib\site-packages\joblib\externals\loky\backend\resource_tracker.py", line 197, in _send
    nbytes = os.write(self._fd, msg)
OSError: [Errno 22] Invalid argument

During handling of the above exception, another exception occurred:

Traceback (most recent call last):
  File "C:\Users\ajink\anaconda3\lib\site-packages\pycaret\internal\pycaret_experiment\supervised_experiment.py", line 809, in compare_models
    model, model_fit_time = self._create_model(**create_model_args)
  File "C:\Users\ajink\anaconda3\lib\site-packages\pycaret\internal\pycaret_experiment\supervised_experiment.py", line 1524, in _create_model
    model, model_fit_time, model_results, _ = self._create_model_with_cv(
  File "C:\Users\ajink\anaconda3\lib\site-packages\pycaret\internal\pycaret_experiment\supervised_experiment.py", line 1116, in _create_model_with_cv
    scores = cross_validate(
  File "C:\Users\ajink\anaconda3\lib\site-packages\sklearn\model_selection\_validation.py", line 267, in cross_validate
    results = parallel(
  File "C:\Users\ajink\anaconda3\lib\site-packages\joblib\parallel.py", line 1008, in __call__
    n_jobs = self._initialize_backend()
  File "C:\Users\ajink\anaconda3\lib\site-packages\joblib\parallel.py", line 775, in _initialize_backend
    n_jobs = self._backend.configure(n_jobs=self.n_jobs, parallel=self,
  File "C:\Users\ajink\anaconda3\lib\site-packages\joblib\_parallel_backends.py", line 506, in configure
    self._workers = get_memmapping_executor(
  File "C:\Users\ajink\anaconda3\lib\site-packages\joblib\executor.py", line 20, in get_memmapping_executor
    return MemmappingExecutor.get_memmapping_executor(n_jobs, **kwargs)
  File "C:\Users\ajink\anaconda3\lib\site-packages\joblib\executor.py", line 42, in get_memmapping_executor
    manager = TemporaryResourcesManager(temp_folder)
  File "C:\Users\ajink\anaconda3\lib\site-packages\joblib\_memmapping_reducer.py", line 535, in __init__
    self.set_current_context(context_id)
  File "C:\Users\ajink\anaconda3\lib\site-packages\joblib\_memmapping_reducer.py", line 539, in set_current_context
    self.register_new_context(context_id)
  File "C:\Users\ajink\anaconda3\lib\site-packages\joblib\_memmapping_reducer.py", line 564, in register_new_context
    self.register_folder_finalizer(new_folder_path, context_id)
  File "C:\Users\ajink\anaconda3\lib\site-packages\joblib\_memmapping_reducer.py", line 594, in register_folder_finalizer
    resource_tracker.register(pool_subfolder, "folder")
  File "C:\Users\ajink\anaconda3\lib\site-packages\joblib\externals\loky\backend\resource_tracker.py", line 178, in register
    self.ensure_running()
  File "C:\Users\ajink\anaconda3\lib\site-packages\joblib\externals\loky\backend\resource_tracker.py", line 99, in ensure_running
    if self._check_alive():
  File "C:\Users\ajink\anaconda3\lib\site-packages\joblib\externals\loky\backend\resource_tracker.py", line 170, in _check_alive
    self._send('PROBE', '', '')
  File "C:\Users\ajink\anaconda3\lib\site-packages\joblib\externals\loky\backend\resource_tracker.py", line 197, in _send
    nbytes = os.write(self._fd, msg)
OSError: [Errno 22] Invalid argument

2022-12-20 20:07:02,940:INFO:Initializing Decision Tree Classifier
2022-12-20 20:07:02,940:INFO:Total runtime is 1.4578714569409688 minutes
2022-12-20 20:07:02,943:INFO:SubProcess create_model() called ==================================
2022-12-20 20:07:02,943:INFO:Initializing create_model()
2022-12-20 20:07:02,943:INFO:create_model(self=<pycaret.classification.oop.ClassificationExperiment object at 0x0000019A10B46FD0>, estimator=dt, fold=StratifiedKFold(n_splits=10, random_state=None, shuffle=False), round=4, cross_validation=True, predict=True, fit_kwargs={}, groups=None, refit=False, probability_threshold=None, experiment_custom_tags=None, verbose=False, system=False, add_to_model_list=True, metrics=None, display=<pycaret.internal.display.display.CommonDisplay object at 0x0000019A0E1E3EB0>, model_only=True, return_train_score=False, kwargs={})
2022-12-20 20:07:02,944:INFO:Checking exceptions
2022-12-20 20:07:02,944:INFO:Importing libraries
2022-12-20 20:07:02,944:INFO:Copying training dataset
2022-12-20 20:07:47,369:WARNING:
'cuml' is a soft dependency and not included in the pycaret installation. Please run: `pip install cuml` to install.
2022-12-20 20:07:47,370:WARNING:
'cuml' is a soft dependency and not included in the pycaret installation. Please run: `pip install cuml` to install.
2022-12-20 20:07:47,370:WARNING:
'cuml' is a soft dependency and not included in the pycaret installation. Please run: `pip install cuml` to install.
2022-12-20 20:07:47,370:WARNING:
'cuml' is a soft dependency and not included in the pycaret installation. Please run: `pip install cuml` to install.
2022-12-20 20:07:48,077:WARNING:
'prophet' is a soft dependency and not included in the pycaret installation. Please run: `pip install prophet` to install.
